Note: you may need to restart the kernel using dbutils.library.restartPython() to use updated packages.
Collecting kaleido
  WARNING: Retrying (Retry(total=4, connect=None, read=None, redirect=None, status=None)) after connection broken by 'SSLError(SSLCertVerificationError(1, '[SSL: CERTIFICATE_VERIFY_FAILED] certificate verify failed: self-signed certificate in certificate chain (_ssl.c:1007)'))': /packages/ae/b3/a0f0f4faac229b0011d8c4a7ee6da7c2dca0b6fd08039c95920846f23ca4/kaleido-0.2.1-py2.py3-none-manylinux1_x86_64.whl
  WARNING: Retrying (Retry(total=3, connect=None, read=None, redirect=None, status=None)) after connection broken by 'SSLError(SSLCertVerificationError(1, '[SSL: CERTIFICATE_VERIFY_FAILED] certificate verify failed: self-signed certificate in certificate chain (_ssl.c:1007)'))': /packages/ae/b3/a0f0f4faac229b0011d8c4a7ee6da7c2dca0b6fd08039c95920846f23ca4/kaleido-0.2.1-py2.py3-none-manylinux1_x86_64.whl
  WARNING: Retrying (Retry(total=2, connect=None, read=None, redirect=None, status=None)) after connection broken by 'SSLError(SSLCertVerificationError(1, '[SSL: CERTIFICATE_VERIFY_FAILED] certificate verify failed: self-signed certificate in certificate chain (_ssl.c:1007)'))': /packages/ae/b3/a0f0f4faac229b0011d8c4a7ee6da7c2dca0b6fd08039c95920846f23ca4/kaleido-0.2.1-py2.py3-none-manylinux1_x86_64.whl
  WARNING: Retrying (Retry(total=1, connect=None, read=None, redirect=None, status=None)) after connection broken by 'SSLError(SSLCertVerificationError(1, '[SSL: CERTIFICATE_VERIFY_FAILED] certificate verify failed: self-signed certificate in certificate chain (_ssl.c:1007)'))': /packages/ae/b3/a0f0f4faac229b0011d8c4a7ee6da7c2dca0b6fd08039c95920846f23ca4/kaleido-0.2.1-py2.py3-none-manylinux1_x86_64.whl
  WARNING: Retrying (Retry(total=0, connect=None, read=None, redirect=None, status=None)) after connection broken by 'SSLError(SSLCertVerificationError(1, '[SSL: CERTIFICATE_VERIFY_FAILED] certificate verify failed: self-signed certificate in certificate chain (_ssl.c:1007)'))': /packages/ae/b3/a0f0f4faac229b0011d8c4a7ee6da7c2dca0b6fd08039c95920846f23ca4/kaleido-0.2.1-py2.py3-none-manylinux1_x86_64.whl
ERROR: Could not install packages due to an OSError: HTTPSConnectionPool(host='files.pythonhosted.org', port=443): Max retries exceeded with url: /packages/ae/b3/a0f0f4faac229b0011d8c4a7ee6da7c2dca0b6fd08039c95920846f23ca4/kaleido-0.2.1-py2.py3-none-manylinux1_x86_64.whl (Caused by SSLError(SSLCertVerificationError(1, '[SSL: CERTIFICATE_VERIFY_FAILED] certificate verify failed: self-signed certificate in certificate chain (_ssl.c:1007)')))
